<?xml version="1.0" ?>
<!-- =================================================================================== -->
<!-- |    This document was autogenerated by xacro from cleaning_robot.urdf.xacro      | -->
<!-- |    EDITING THIS FILE BY HAND IS NOT RECOMMENDED                                 | -->
<!-- =================================================================================== -->
<robot name="cleaning_robot">
  <!--Colors-->
  <material name="Gray">
    <color rgba="0.6 1 0.8 1"/>
  </material>
  <material name="DarkGray">
    <color rgba="0.3 0.3 0.3 1"/>
  </material>
  <material name="Orange">
    <color rgba="1 0.6 0 1"/>
  </material>
  <material name="Purple">
    <color rgba="1 0 1 1"/>
  </material>
  <material name="DarkOrange">
    <color rgba="0.7 0.42 0 1"/>
  </material>
  <material name="Green">
    <color rgba="0 1 0 1"/>
  </material>
  <material name="Red">
    <color rgba="1 0 0 1"/>
  </material>
  <material name="Blue">
    <color rgba="0.0 0.0 0.8 1.0"/>
  </material>
  <material name="White">
    <color rgba="1.0 1.0 1.0 1.0"/>
  </material>
  <link name="base_footprint">
    <inertial>
      <mass value="0.0001"/>
      <origin xyz="0 0 0"/>
      <inertia ixx="0.0001" ixy="0.0" ixz="0.0" iyy="0.0001" iyz="0.0" izz="0.0001"/>
    </inertial>
    <visual>
      <origin rpy="0 0 0" xyz="0 0 0"/>
      <geometry>
        <box size="0.001 0.001 0.001"/>
      </geometry>
    </visual>
  </link>
  <link name="base_link">
    <inertial>
      <mass value="5.0"/>
      <origin xyz="0 0 0"/>
      <inertia ixx="0.8316666666666667" ixy="0.0" ixz="0.0" iyy="0.8316666666666667" iyz="0.0" izz="1.5625"/>
    </inertial>
    <visual>
      <origin rpy="0 0 0" xyz="0 0 0"/>
      <geometry>
        <cylinder length="0.11" radius="0.25"/>
      </geometry>
      <material name="White"/>
    </visual>
    <collision>
      <origin rpy="0 0 0" xyz="0 0 0"/>
      <geometry>
        <cylinder length="0.11" radius="0.25"/>
      </geometry>
    </collision>
  </link>
  <link name="caster_rotator">
    <inertial>
      <mass value="0.15"/>
      <origin xyz="0 0 0"/>
      <inertia ixx="0.001" ixy="0.0" ixz="0.0" iyy="0.001" iyz="0.0" izz="0.001"/>
    </inertial>
    <visual>
      <geometry>
        <cylinder length="0.06" radius="0.015"/>
      </geometry>
      <material name="Purple"/>
    </visual>
    <collision>
      <geometry>
        <cylinder length="0.06" radius="0.015"/>
      </geometry>
    </collision>
  </link>
  <link name="caster">
    <inertial>
      <mass value="0.15"/>
      <origin xyz="0 0 0"/>
      <inertia ixx="0.001" ixy="0.0" ixz="0.0" iyy="0.001" iyz="0.0" izz="0.001"/>
    </inertial>
    <visual>
      <geometry>
        <cylinder length="0.02" radius="0.025"/>
      </geometry>
      <material name="DarkOrange"/>
    </visual>
    <collision>
      <geometry>
        <cylinder length="0.02" radius="0.025"/>
      </geometry>
    </collision>
  </link>
  <link name="brush_lift">
    <inertial>
      <mass value="0.15"/>
      <origin xyz="0 0 0"/>
      <inertia ixx="0.001" ixy="0.0" ixz="0.0" iyy="0.001" iyz="0.0" izz="0.001"/>
    </inertial>
    <visual>
      <geometry>
        <cylinder length="0.1" radius="0.0075"/>
      </geometry>
      <material name="Green"/>
    </visual>
    <collision>
      <geometry>
        <cylinder length="0.1" radius="0.0075"/>
      </geometry>
    </collision>
  </link>
  <link name="left_brush_connector1">
    <inertial>
      <mass value="0.15"/>
      <origin xyz="0 0 0"/>
      <inertia ixx="0.001" ixy="0.0" ixz="0.0" iyy="0.001" iyz="0.0" izz="0.001"/>
    </inertial>
    <visual>
      <geometry>
        <cylinder length="0.09" radius="0.0075"/>
      </geometry>
      <material name="Green"/>
    </visual>
    <collision>
      <geometry>
        <cylinder length="0.09" radius="0.0075"/>
      </geometry>
    </collision>
  </link>
  <link name="left_brush_connector2">
    <inertial>
      <mass value="0.15"/>
      <origin xyz="0 0 0"/>
      <inertia ixx="0.001" ixy="0.0" ixz="0.0" iyy="0.001" iyz="0.0" izz="0.001"/>
    </inertial>
    <visual>
      <geometry>
        <cylinder length="0.025" radius="0.0075"/>
      </geometry>
      <material name="Green"/>
    </visual>
    <collision>
      <geometry>
        <cylinder length="0.025" radius="0.0075"/>
      </geometry>
    </collision>
  </link>
  <link name="right_brush_connector1">
    <inertial>
      <mass value="0.15"/>
      <origin xyz="0 0 0"/>
      <inertia ixx="0.001" ixy="0.0" ixz="0.0" iyy="0.001" iyz="0.0" izz="0.001"/>
    </inertial>
    <visual>
      <geometry>
        <cylinder length="0.09" radius="0.0075"/>
      </geometry>
      <material name="Green"/>
    </visual>
    <collision>
      <geometry>
        <cylinder length="0.09" radius="0.0075"/>
      </geometry>
    </collision>
  </link>
  <link name="right_brush_connector2">
    <inertial>
      <mass value="0.15"/>
      <origin xyz="0 0 0"/>
      <inertia ixx="0.001" ixy="0.0" ixz="0.0" iyy="0.001" iyz="0.0" izz="0.001"/>
    </inertial>
    <visual>
      <geometry>
        <cylinder length="0.025" radius="0.0075"/>
      </geometry>
      <material name="Green"/>
    </visual>
    <collision>
      <geometry>
        <cylinder length="0.025" radius="0.0075"/>
      </geometry>
    </collision>
  </link>
  <link name="left_brush">
    <inertial>
      <mass value="0.15"/>
      <origin xyz="0 0 0"/>
      <inertia ixx="0.001" ixy="0.0" ixz="0.0" iyy="0.001" iyz="0.0" izz="0.001"/>
    </inertial>
    <visual>
      <geometry>
        <cylinder length="0.01" radius="0.065"/>
      </geometry>
      <material name="Green"/>
    </visual>
    <collision>
      <geometry>
        <cylinder length="0.01" radius="0.065"/>
      </geometry>
    </collision>
  </link>
  <link name="right_brush">
    <inertial>
      <mass value="0.15"/>
      <origin xyz="0 0 0"/>
      <inertia ixx="0.001" ixy="0.0" ixz="0.0" iyy="0.001" iyz="0.0" izz="0.001"/>
    </inertial>
    <visual>
      <geometry>
        <cylinder length="0.01" radius="0.065"/>
      </geometry>
      <material name="Green"/>
    </visual>
    <collision>
      <geometry>
        <cylinder length="0.01" radius="0.065"/>
      </geometry>
    </collision>
  </link>
  <link name="hokuyo_link">
    <visual>
      <origin rpy="0 0 0" xyz="0 0 0"/>
      <geometry>
        <box size="0.05 0.05 0.05"/>
      </geometry>
      <material name="Blue"/>
    </visual>
  </link>
  <joint name="base_link_joint" type="fixed">
    <origin rpy="0 0 0" xyz="0 0 0.125"/>
    <parent link="base_footprint"/>
    <child link="base_link"/>
  </joint>
  <joint name="caster_rotator_joint" type="fixed">
    <origin rpy="0 0 0" xyz="-0.18 0 -0.06"/>
    <parent link="base_link"/>
    <child link="caster_rotator"/>
    <axis xyz="0 0 1"/>
  </joint>
  <joint name="caster_joint" type="continuous">
    <origin rpy="1.57079632679 0 0" xyz="-0.02 0 -0.03"/>
    <parent link="caster_rotator"/>
    <child link="caster"/>
    <axis xyz="0 0 1"/>
    <dynamics damping="10" friction="0.05"/>
  </joint>
  <joint name="brush_lift_joint" type="prismatic">
    <origin rpy="0 0 1.57079632679" xyz="0.2 0 -0.055"/>
    <parent link="base_link"/>
    <child link="brush_lift"/>
    <axis xyz="0 0 1"/>
    <limit effort="30" lower="0" upper="0.035" velocity="1.0"/>
  </joint>
  <joint name="left_brush_connector1_joint" type="fixed">
    <origin rpy="0 1.57079632679 0" xyz="0.04 0 -0.04"/>
    <parent link="brush_lift"/>
    <child link="left_brush_connector1"/>
    <axis xyz="0 0 1"/>
  </joint>
  <joint name="right_brush_connector1_joint" type="fixed">
    <origin rpy="0 1.57079632679 0" xyz="-0.04 0 -0.04"/>
    <parent link="brush_lift"/>
    <child link="right_brush_connector1"/>
    <axis xyz="0 0 1"/>
  </joint>
  <joint name="left_brush_connector2_joint" type="fixed">
    <origin rpy="0 -1.57079632679 0" xyz="0 0.008 0.04"/>
    <parent link="left_brush_connector1"/>
    <child link="left_brush_connector2"/>
    <axis xyz="0 0 1"/>
  </joint>
  <joint name="right_brush_connector2_joint" type="fixed">
    <origin rpy="0 -1.57079632679 0" xyz="0 0.008 -0.04"/>
    <parent link="right_brush_connector1"/>
    <child link="right_brush_connector2"/>
    <axis xyz="0 0 1"/>
  </joint>
  <joint name="left_brush_joint" type="continuous">
    <origin rpy="0 0 0" xyz="0 0 -0.01"/>
    <parent link="left_brush_connector2"/>
    <child link="left_brush"/>
    <axis xyz="0 0 1"/>
  </joint>
  <joint name="right_brush_joint" type="continuous">
    <origin rpy="0 0 0" xyz="0 0 -0.01"/>
    <parent link="right_brush_connector2"/>
    <child link="right_brush"/>
    <axis xyz="0 0 -1"/>
  </joint>
  <joint name="hokuyo_joint" type="fixed">
    <origin rpy="0 0 0" xyz="0.225 0 0.08"/>
    <parent link="base_link"/>
    <child link="hokuyo_link"/>
  </joint>
  <link name="front_right_wheel">
    <visual>
      <origin rpy="1.57079632679 0 0" xyz="0 0 0"/>
      <geometry>
        <cylinder length="0.03" radius="0.065"/>
      </geometry>
      <material name="DarkGray"/>
    </visual>
    <collision>
      <origin rpy="1.57079632679 0 0" xyz="0 0 0"/>
      <geometry>
        <cylinder length="0.03" radius="0.065"/>
      </geometry>
    </collision>
    <inertial>
      <mass value="0.2"/>
      <origin xyz="0 0 0"/>
      <inertia ixx="0.0022625" ixy="0.0" ixz="0.0" iyy="0.0022625" iyz="0.0" izz="0.0042250000000000005"/>
    </inertial>
  </link>
  <gazebo reference="front_right_wheel">
    <mu1 value="1.0"/>
    <mu2 value="1.0"/>
    <kp value="10000000.0"/>
    <kd value="1.0"/>
    <fdir1 value="1 0 0"/>
    <material>Gazebo/Grey</material>
    <turnGravityOff>false</turnGravityOff>
  </gazebo>
  <joint name="front_right_wheel_joint" type="continuous">
    <parent link="base_link"/>
    <child link="front_right_wheel"/>
    <origin rpy="0 0 0" xyz="0.06 -0.156 -0.05"/>
    <axis rpy="0 0 0" xyz="0 1 0"/>
    <limit effort="100" velocity="100"/>
    <dynamics damping="20" friction="0.03"/>
  </joint>
  <!-- Transmission is important to link the joints and the controller -->
  <transmission name="front_right_wheel_joint_trans">
    <type>transmission_interface/SimpleTransmission</type>
    <joint name="front_right_wheel_joint"/>
    <actuator name="front_right_wheel_joint_motor">
      <hardwareInterface>EffortJointInterface</hardwareInterface>
      <mechanicalReduction>1</mechanicalReduction>
    </actuator>
  </transmission>
  <link name="front_left_wheel">
    <visual>
      <origin rpy="1.57079632679 0 0" xyz="0 0 0"/>
      <geometry>
        <cylinder length="0.03" radius="0.065"/>
      </geometry>
      <material name="DarkGray"/>
    </visual>
    <collision>
      <origin rpy="1.57079632679 0 0" xyz="0 0 0"/>
      <geometry>
        <cylinder length="0.03" radius="0.065"/>
      </geometry>
    </collision>
    <inertial>
      <mass value="0.2"/>
      <origin xyz="0 0 0"/>
      <inertia ixx="0.0022625" ixy="0.0" ixz="0.0" iyy="0.0022625" iyz="0.0" izz="0.0042250000000000005"/>
    </inertial>
  </link>
  <gazebo reference="front_left_wheel">
    <mu1 value="1.0"/>
    <mu2 value="1.0"/>
    <kp value="10000000.0"/>
    <kd value="1.0"/>
    <fdir1 value="1 0 0"/>
    <material>Gazebo/Grey</material>
    <turnGravityOff>false</turnGravityOff>
  </gazebo>
  <joint name="front_left_wheel_joint" type="continuous">
    <parent link="base_link"/>
    <child link="front_left_wheel"/>
    <origin rpy="0 0 0" xyz="0.06 0.156 -0.05"/>
    <axis rpy="0 0 0" xyz="0 1 0"/>
    <limit effort="100" velocity="100"/>
    <dynamics damping="20" friction="0.03"/>
  </joint>
  <!-- Transmission is important to link the joints and the controller -->
  <transmission name="front_left_wheel_joint_trans">
    <type>transmission_interface/SimpleTransmission</type>
    <joint name="front_left_wheel_joint"/>
    <actuator name="front_left_wheel_joint_motor">
      <hardwareInterface>EffortJointInterface</hardwareInterface>
      <mechanicalReduction>1</mechanicalReduction>
    </actuator>
  </transmission>
  <gazebo reference="base_footprint">
    <turnGravityOff>false</turnGravityOff>
  </gazebo>
  <gazebo reference="base_link">
    <material>Gazebo/White</material>
    <turnGravityOff>false</turnGravityOff>
  </gazebo>
  <gazebo reference="caster_rotator">
    <turnGravityOff>false</turnGravityOff>
  </gazebo>
  <gazebo reference="caster">
    <turnGravityOff>false</turnGravityOff>
  </gazebo>
  <gazebo reference="brush_lift">
    <turnGravityOff>false</turnGravityOff>
  </gazebo>
  <gazebo reference="left_brush_connector1">
    <turnGravityOff>false</turnGravityOff>
  </gazebo>
  <gazebo reference="left_brush_connector2">
    <turnGravityOff>false</turnGravityOff>
  </gazebo>
  <gazebo reference="right_brush_connector1">
    <turnGravityOff>false</turnGravityOff>
  </gazebo>
  <gazebo reference="right_brush_connector2">
    <turnGravityOff>false</turnGravityOff>
  </gazebo>
  <gazebo reference="left_brush">
    <turnGravityOff>false</turnGravityOff>
  </gazebo>
  <gazebo reference="right_brush">
    <turnGravityOff>false</turnGravityOff>
  </gazebo>
  <gazebo reference="hokuyo_link">
    <material>Gazebo/Blue</material>
    <turnGravityOff>false</turnGravityOff>
    <sensor name="head_hokuyo_sensor" type="ray">
      <pose>0.025 0 0 0 0 0</pose>
      <visualize>false</visualize>
      <update_rate>40</update_rate>
      <ray>
        <scan>
          <horizontal>
            <samples>720</samples>
            <resolution>1</resolution>
            <min_angle>-1.57079632679</min_angle>
            <max_angle>1.57079632679</max_angle>
          </horizontal>
        </scan>
        <range>
          <min>0.10</min>
          <max>10.0</max>
          <resolution>0.001</resolution>
        </range>
      </ray>
      <plugin filename="libgazebo_ros_laser.so" name="gazebo_ros_head_hokuyo_controller">
        <topicName>/scan</topicName>
        <frameName>hokuyo_link</frameName>
      </plugin>
    </sensor>
  </gazebo>
  <gazebo>
    <plugin filename="libgazebo_ros_diff_drive.so" name="differential_drive_controller">
      <legacyMode>true</legacyMode>
      <rosDebugLevel>Debug</rosDebugLevel>
      <publishWheelTF>false</publishWheelTF>
      <robotNamespace>/</robotNamespace>
      <publishTf>1</publishTf>
      <publishWheelJointState>false</publishWheelJointState>
      <alwaysOn>true</alwaysOn>
      <updateRate>100.0</updateRate>
      <leftJoint>front_left_wheel_joint</leftJoint>
      <rightJoint>front_right_wheel_joint</rightJoint>
      <wheelSeparation>0.5</wheelSeparation>
      <wheelDiameter>0.13</wheelDiameter>
      <broadcastTF>1</broadcastTF>
      <wheelTorque>30</wheelTorque>
      <wheelAcceleration>1.5</wheelAcceleration>
      <commandTopic>cmd_vel</commandTopic>
      <odometryFrame>odom</odometryFrame>
      <odometryTopic>odom</odometryTopic>
      <robotBaseFrame>base_footprint</robotBaseFrame>
    </plugin>
  </gazebo>
</robot>

