<?xml version="1.0"?>
<robot name="WHEELS" xmlns:xacro="https://www.ros.org/wiki/xacro">

    <xacro:macro name="wheel" params="fb lr parent translateX translateY flipY"> 
        <link name="${fb}_${lr}_wheel">
            <visual>
                <origin xyz="0 0 0" rpy="${flipY*M_PI_2} 0 0" /> 
                <geometry>
                    <cylinder length="${whl_h}" radius="${whl_r}" />
                </geometry>
                <material name="DarkGray" />
            </visual>
            <collision>
                <origin xyz="0 0 0" rpy="${flipY*M_PI_2} 0 0" />
                <geometry>
                    <cylinder length="${whl_h}" radius="${whl_r}" />
                </geometry>
            </collision>
            <inertial>
                <mass value="${whl_m}" />
                <origin xyz="0 0 0" />
                <xacro:cylinder_inertia  m="${whl_m}" r="${whl_r}" h="${whl_h}" />
            </inertial>
        </link>

        <gazebo reference="${fb}_${lr}_wheel">
            <mu1 value="1.0"/>
            <mu2 value="1.0"/>
            <kp  value="10000000.0" />
            <kd  value="1.0" />
            <fdir1 value="1 0 0"/>
            <material>Gazebo/Grey</material>
            <turnGravityOff>false</turnGravityOff>
        </gazebo>

        <joint name="${fb}_${lr}_wheel_joint" type="continuous">
            <parent link="${parent}"/>
            <child link="${fb}_${lr}_wheel"/>
            <origin xyz="${translateX * base_x_to_wheel} ${translateY * base_y_to_wheel} ${-base_z_to_wheel}" rpy="0 0 0" /> 
            <axis xyz="0 1 0" rpy="0 0 0" />
            <limit effort="100" velocity="100"/>
            <joint_properties damping="0.0" friction="0.0"/>
        </joint>

    <!-- Transmission is important to link the joints and the controller -->
        <transmission name="${fb}_${lr}_wheel_joint_trans">
            <type>transmission_interface/SimpleTransmission</type>
            <joint name="${fb}_${lr}_wheel_joint" />
            <actuator name="${fb}_${lr}_wheel_joint_motor">
                <hardwareInterface>EffortJointInterface</hardwareInterface>
                <mechanicalReduction>1</mechanicalReduction>
            </actuator>
        </transmission>
   
    </xacro:macro>
</robot>